#VRML_SIM R2023b utf8

EXTERNPROTO "https://raw.githubusercontent.com/cyberbotics/webots/R2023b/projects/objects/backgrounds/protos/TexturedBackground.proto"
EXTERNPROTO "https://raw.githubusercontent.com/cyberbotics/webots/R2023b/projects/objects/backgrounds/protos/TexturedBackgroundLight.proto"
EXTERNPROTO "https://raw.githubusercontent.com/cyberbotics/webots/R2023b/projects/objects/floors/protos/RectangleArena.proto"

WorldInfo {
  info [
    "Example use of a Bumper TouchSensor device."
  ]
  title "Bumper"
}
Viewpoint {
  orientation 0.4412990772475651 -0.48138755323914045 -0.7573117904845278 4.879290988680834
  position -0.3157411148544142 -0.47610815103741044 0.8920557715771349
}
TexturedBackground {
}
TexturedBackgroundLight {
}
RectangleArena {
}
DEF GREEN_BOX Solid {
  translation -0.29 0.08 0.05
  children [
    Shape {
      appearance PBRAppearance {
        baseColor 0 1 0
        roughness 0.2189099510000001
        metalness 0
      }
      geometry DEF BOX0 Box {
        size 0.23 0.1 0.1
      }
    }
  ]
  name "green box"
  boundingObject Shape {
    appearance PBRAppearance {
      roughness 1.1102230246251565e-16
      metalness 0
    }
    geometry USE BOX0
  }
}
DEF BLUE_BOX Solid {
  translation 0.2 -0.27 0.05
  rotation 0 0 -1 -1.880795
  children [
    Shape {
      appearance PBRAppearance {
        baseColor 0 0 1
        roughness 0.519341125
        metalness 0
      }
      geometry DEF BOX1 Box {
        size 0.1 0.1 0.1
      }
    }
  ]
  name "blue box"
  boundingObject Shape {
    appearance PBRAppearance {
      roughness 1.1102230246251565e-16
      metalness 0
    }
    geometry USE BOX1
  }
}
DEF YELLOW_BOX Solid {
  translation -0.338165 -0.20841 0.05
  rotation -0.9612795880715977 -0.19486091649802306 -0.19486091649802306 -1.6102753071795863
  children [
    Shape {
      appearance PBRAppearance {
        baseColor 1 1 0
        roughness 0.03934117200000009
        metalness 0
      }
      geometry DEF BOX2 Box {
        size 0.05 0.1 0.3
      }
    }
  ]
  name "yellow box"
  boundingObject Shape {
    appearance PBRAppearance {
      roughness 1.1102230246251565e-16
      metalness 0
    }
    geometry USE BOX2
  }
}
DEF PINK_BOX Solid {
  translation 0.42 0.1 0.05
  children [
    Shape {
      appearance PBRAppearance {
        baseColor 1 0.1 0.3
        roughness 0.16827074099999995
        metalness 0
      }
      geometry DEF BOX3 Box {
        size 0.15 0.1 0.08
      }
    }
  ]
  name "red box"
  boundingObject Shape {
    appearance PBRAppearance {
      roughness 1.1102230246251565e-16
      metalness 0
    }
    geometry USE BOX3
  }
}
Robot {
  translation -0.245713 0.306578 0.0025066
  rotation 0.051822777078344276 0.02210031418255578 -0.9984117266383246 1.7671795223925026
  children [
    Speaker {
      translation 0 0 0.085
      children [
        Shape {
          appearance PBRAppearance {
            baseColor 0.2 0.2 0.2
            baseColorMap ImageTexture {
              url [
                "https://raw.githubusercontent.com/cyberbotics/webots/R2023b/projects/samples/devices/worlds/textures/speaker.png"
              ]
            }
            roughness 0.5
            metalness 0
          }
          geometry Cylinder {
            height 0.01
            radius 0.03
            side FALSE
            subdivision 24
          }
        }
        Shape {
          appearance PBRAppearance {
            baseColor 0.2 0.2 0.2
            roughness 1
            metalness 0
          }
          geometry Cylinder {
            height 0.01
            radius 0.03
            top FALSE
            subdivision 24
          }
        }
      ]
    }
    Propeller {
      shaftAxis -0.006 0 1
      centerOfThrust 0 0 0.19
      thrustConstants 0.001 0.001
      torqueConstants 1e-07 1e-07
      device RotationalMotor {
        name "prop motor"
        acceleration 50
        maxVelocity 400
        maxTorque 15
        sound ""
      }
      fastHelix DEF FAST_HELIX Solid {
        translation 0 0 0.11
        children [
          DEF FAST_MAIN_HELIX_SHAPE Shape {
            appearance DEF FAST_HELIX_APPEARANCE PBRAppearance {
              baseColorMap ImageTexture {
                url [
                  "https://raw.githubusercontent.com/cyberbotics/webots/R2023b/projects/samples/devices/worlds/textures/blurred_helix.png"
                ]
              }
              transparency 0.5
              roughness 0.5
              metalness 0
            }
            geometry Cylinder {
              height 0.003
              radius 0.145
              side FALSE
              subdivision 24
            }
          }
        ]
      }
      slowHelix DEF SLOW_HELIX Solid {
        translation 0 -2.94113e-08 0.11
        rotation -1 0 0 -1.570796
        children [
          DEF SLOW_MAIN_HELIX_TRANSFORM Pose {
            rotation 0 0 1 1.570796
            children [
              DEF SLOW_MAIN_HELIX_GROUP Group {
                children [
                  Shape {
                    geometry Capsule {
                      height 0.02
                      radius 0.01
                    }
                  }
                  Shape {
                    geometry Cylinder {
                      height 0.07
                      radius 0.004
                    }
                  }
                  DEF RIGHT_BLADE Pose {
                    translation 0 0 0.09
                    rotation 0 0 1 0.361801
                    children [
                      DEF BLADE_SHAPE Shape {
                        appearance PBRAppearance {
                          baseColor 0.8 0.8 0.8
                          roughness 1
                          metalness 0
                        }
                        geometry Box {
                          size 0.01 0.004 0.11
                        }
                      }
                    ]
                  }
                  DEF RIGHT_BLADE Pose {
                    translation 0 0 -0.09
                    rotation 0 0 1 -0.361799
                    children [
                      DEF BLADE_SHAPE Shape {
                        appearance PBRAppearance {
                          baseColor 0.8 0.8 0.8
                          roughness 1
                          metalness 0
                        }
                        geometry Box {
                          size 0.01 0.004 0.11
                        }
                      }
                    ]
                  }
                ]
              }
            ]
          }
        ]
      }
    }
    Pose {
      translation 0 0 0.0415
      rotation 0 0 1 1.570796
      children [
        Shape {
          appearance PBRAppearance {
            baseColor 0.0820075 0.364731 0.8
            roughness 1
            metalness 0
          }
          geometry DEF BODY Cylinder {
            height 0.08
            radius 0.045
          }
        }
      ]
    }
    HingeJoint {
      jointParameters HingeJointParameters {
        position -352.335388862106
        axis 0 1 0
        anchor 0 0 0.025
      }
      device [
        RotationalMotor {
          name "left wheel motor"
          consumptionFactor 70
          maxVelocity 40
          maxTorque 100
        }
        PositionSensor {
          name "left wheel sensor"
        }
      ]
      endPoint Solid {
        translation -0.006659905231935864 0.04577289999999998 0.021168641562052264
        rotation -0.23436821890247275 0.23060192324485881 0.9444015517587077 4.633772467396417
        children [
          DEF WHEEL Pose {
            rotation 0.577656895078166 0.5771968951617173 -0.5771968951617173 -2.093935
            children [
              Shape {
                appearance PBRAppearance {
                  baseColor 1 0 0
                  roughness 1
                  metalness 0
                }
                geometry Cylinder {
                  height 0.01
                  radius 0.025
                }
              }
            ]
          }
        ]
        name "left wheel"
        boundingObject USE WHEEL
        physics DEF PHYSICS_WHEEL Physics {
          density -1
          mass 0.05
        }
      }
    }
    HingeJoint {
      jointParameters HingeJointParameters {
        position 954.4920067439581
        axis 0 1 0
        anchor 0 0 0.025
      }
      device [
        RotationalMotor {
          name "right wheel motor"
          consumptionFactor 70
          maxVelocity 40
          maxTorque 100
        }
        PositionSensor {
          name "right wheel sensor"
        }
      ]
      endPoint Solid {
        translation 0.007727906072296795 -0.045857699999999994 0.023987996382339297
        rotation 0.4103328445020982 -0.4146547376948337 -0.8122120444994927 1.8028385969029992
        children [
          USE WHEEL
        ]
        name "right wheel"
        boundingObject USE WHEEL
        physics USE PHYSICS_WHEEL
      }
    }
    Pose {
      translation 0.0385 -0.02 0.063
      rotation -0.726828171413359 -0.4856551145357015 -0.48565411453546564 -1.884582
      children [
        DEF UNUSED_EYE Group {
          children [
            Pose {
              translation 0 0 1e-05
              rotation 0 0 1 0.8
              children [
                Shape {
                  appearance PBRAppearance {
                    baseColor 0.975691 0.981481 0.0252992
                    roughness 1
                    metalness 0
                  }
                  geometry Box {
                    size 0.02 0.005 0.005
                  }
                }
              ]
            }
            Pose {
              rotation 0 0 1 -0.8
              children [
                Shape {
                  appearance PBRAppearance {
                    baseColor 0.975691 0.981481 0.0252992
                    roughness 1
                    metalness 0
                  }
                  geometry Box {
                    size 0.02 0.005 0.005
                  }
                }
              ]
            }
          ]
        }
      ]
    }
    Pose {
      translation 0.0385 0.02 0.063
      rotation -0.7268306455324123 0.4856527631523045 0.4856527631523045 -1.884578
      children [
        USE UNUSED_EYE
      ]
    }
    Shape {
      appearance PBRAppearance {
        baseColor 0.8 0.8 0.8
        baseColorMap ImageTexture {
          url [
            "https://raw.githubusercontent.com/cyberbotics/webots/R2023b/projects/samples/devices/worlds/textures/mybot.png"
          ]
        }
        roughness 0.5
        metalness 0
      }
      geometry IndexedFaceSet {
        coord Coordinate {
          point [
            0.015 0.038 -0.041
            0.015 0.023 -0.041
            0 0.023 -0.0455
            -0.015 0.023 -0.041
            -0.015 0.038 -0.041
            0 0.038 -0.0455
          ]
        }
        texCoord TextureCoordinate {
          point [
            0 0
            0.5 0
            1 0
            1 1
            0.5 1
            0 1
          ]
        }
        coordIndex [
          0, 1, 2, 5, -1, 5, 2, 3, 4, -1
        ]
        texCoordIndex [
          5, 0, 1, 4, -1, 4, 1, 2, 3, -1
        ]
        creaseAngle 0.9
      }
    }
    TouchSensor {
      translation 0.05485237069009921 -0.0060936758983494155 0.03730167595891652
      rotation 0.9999999999999999 -8.996502117711035e-09 -7.907919192737326e-09 -3.141592387651715
      children [
        Shape {
          appearance PBRAppearance {
            baseColor 0 0 0
            roughness 0.6980390000000001
            metalness 0
          }
          geometry DEF BUMPER Box {
            size 0.02 0.09 0.02
          }
        }
      ]
      name "bumper"
      boundingObject USE BUMPER
      physics Physics {
        density -1
        mass 0.01
      }
      lookupTable [
        0 0 0
        0.01 1 0
      ]
    }
  ]
  name "mybot"
  boundingObject Pose {
    translation 0 0 0.0415
    rotation 0 0 1 1.570796
    children [
      USE BODY
    ]
  }
  physics Physics {
    density -1
    mass 0.5
  }
  controller "bumper"
  cpuConsumption 100
}
